<?xml version="1.0" ?>
<robot name="gripper_a">

<link name="gripper_a_base_link">
  <inertial>
    <origin xyz="-7.377384471738979e-15 0.0 0.003077681810644516" rpy="0 0 0"/>
    <mass value="0.028323974793777462"/>
    <inertia ixx="2e-06" iyy="2e-06" izz="4e-06" ixy="-0.0" iyz="0.0" ixz="0.0"/>
  </inertial>
  <visual>
    <origin xyz="0 0 0" rpy="0 0 0"/>
    <geometry>
      <mesh filename="meshes/gripper_a_base_link.stl" scale="0.001 0.001 0.001"/>
    </geometry>
    <material name="silver"/>
  </visual>
  <collision>
    <origin xyz="0 0 0" rpy="0 0 0"/>
    <geometry>
      <mesh filename="meshes/gripper_a_base_link.stl" scale="0.001 0.001 0.001"/>
    </geometry>
  </collision>
</link>

<link name="gripper_a_gl_1">
  <inertial>
    <origin xyz="0.006908917643153909 0.0 0.012037201025252875" rpy="0 0 0"/>
    <mass value="0.02257569481798892"/>
    <inertia ixx="2e-06" iyy="2e-06" izz="1e-06" ixy="0.0" iyz="0.0" ixz="-0.0"/>
  </inertial>
  <visual>
    <origin xyz="-0.0 -0.0 -0.01" rpy="0 0 0"/>
    <geometry>
      <mesh filename="meshes/gripper_a_gl_1.stl" scale="0.001 0.001 0.001"/>
    </geometry>
    <material name="silver"/>
  </visual>
  <collision>
    <origin xyz="-0.0 -0.0 -0.01" rpy="0 0 0"/>
    <geometry>
      <mesh filename="meshes/gripper_a_gl_1.stl" scale="0.001 0.001 0.001"/>
    </geometry>
  </collision>
</link>

<link name="gripper_a_gr_1">
  <inertial>
    <origin xyz="-0.006998007090120641 0.005999999999999998 0.012235716657799047" rpy="0 0 0"/>
    <mass value="0.02210404358591467"/>
    <inertia ixx="2e-06" iyy="2e-06" izz="1e-06" ixy="-0.0" iyz="-0.0" ixz="0.0"/>
  </inertial>
  <visual>
    <origin xyz="-0.0 0.006 -0.01" rpy="0 0 0"/>
    <geometry>
      <mesh filename="meshes/gripper_a_gr_1.stl" scale="0.001 0.001 0.001"/>
    </geometry>
    <material name="silver"/>
  </visual>
  <collision>
    <origin xyz="-0.0 0.006 -0.01" rpy="0 0 0"/>
    <geometry>
      <mesh filename="meshes/gripper_a_gr_1.stl" scale="0.001 0.001 0.001"/>
    </geometry>
  </collision>
</link>

<link name="gripper_a_AP_1">
  <inertial>
    <origin xyz="1.3877787807814462e-19 0.0 -4.506096355706241e-19" rpy="0 0 0"/>
    <mass value="3.288200310757325e-05"/>
    <inertia ixx="0.0" iyy="0.0" izz="0.0" ixy="0.0" iyz="-0.0" ixz="0.0"/>
  </inertial>
  
  
</link>

<joint name="Revolute 1" type="revolute">
  <origin xyz="0.0 0.0 0.01" rpy="0 0 0"/>
  <parent link="gripper_a_base_link"/>
  <child link="gripper_a_gl_1"/>
  <axis xyz="0.0 1.0 0.0"/>
  <limit upper="0.785398" lower="0.0" effort="100" velocity="100"/>
</joint>

<joint name="Revolute 2" type="revolute">
  <origin xyz="0.0 -0.006 0.01" rpy="0 0 0"/>
  <parent link="gripper_a_base_link"/>
  <child link="gripper_a_gr_1"/>
  <axis xyz="0.0 1.0 0.0"/>
  <limit upper="0.0" lower="-0.785398" effort="100" velocity="100"/>
</joint>

<joint name="Rigid 4" type="fixed">
  <origin xyz="0.0 0.0 0.0" rpy="0 0 0"/>
  <parent link="gripper_a_base_link"/>
  <child link="gripper_a_AP_1"/>
</joint>

</robot>
