<?xml version="1.0" ?>
<robot name="prismatic_j">

<link name="prismatic_j_base_link">
  <inertial>
    <origin xyz="0.025899332662723817 -1.9256593420022088e-18 -5.776978026006627e-18" rpy="0 0 0"/>
    <mass value="0.07241364495338641"/>
    <inertia ixx="7e-06" iyy="2.4e-05" izz="2.4e-05" ixy="-0.0" iyz="-0.0" ixz="-0.0"/>
  </inertial>
  <visual>
    <origin xyz="0 0 0" rpy="0 0 0"/>
    <geometry>
      <mesh filename="meshes/prismatic_j_base_link.stl" scale="0.001 0.001 0.001"/>
    </geometry>
    <material name="silver"/>
  </visual>
  <collision>
    <origin xyz="0 0 0" rpy="0 0 0"/>
    <geometry>
      <mesh filename="meshes/prismatic_j_base_link.stl" scale="0.001 0.001 0.001"/>
    </geometry>
  </collision>
</link>

<link name="prismatic_j_slider_1">
  <inertial>
    <origin xyz="0.027843325541787315 0.0 -0.01" rpy="0 0 0"/>
    <mass value="0.10875740809788849"/>
    <inertia ixx="5e-06" iyy="3.5e-05" izz="3.5e-05" ixy="0.0" iyz="0.0" ixz="-0.0"/>
  </inertial>
  <visual>
    <origin xyz="-0.005 -0.0 -0.01" rpy="0 0 0"/>
    <geometry>
      <mesh filename="meshes/prismatic_j_slider_1.stl" scale="0.001 0.001 0.001"/>
    </geometry>
    <material name="silver"/>
  </visual>
  <collision>
    <origin xyz="-0.005 -0.0 -0.01" rpy="0 0 0"/>
    <geometry>
      <mesh filename="meshes/prismatic_j_slider_1.stl" scale="0.001 0.001 0.001"/>
    </geometry>
  </collision>
</link>

<link name="prismatic_j_APP_1">
  <inertial>
    <origin xyz="6.661338147750939e-18 0.0 0.0" rpy="0 0 0"/>
    <mass value="3.288200310757315e-05"/>
    <inertia ixx="0.0" iyy="0.0" izz="0.0" ixy="-0.0" iyz="0.0" ixz="0.0"/>
  </inertial>
  
  
</link>

<link name="prismatic_j_APC_1">
  <inertial>
    <origin xyz="1.3877787807814457e-17 -1.6653345369377347e-18 4.440892098500626e-18" rpy="0 0 0"/>
    <mass value="3.288200310757315e-05"/>
    <inertia ixx="0.0" iyy="0.0" izz="0.0" ixy="-0.0" iyz="-0.0" ixz="0.0"/>
  </inertial>
  
  
</link>

<joint name="Slider 1" type="prismatic">
  <origin xyz="0.005 0.0 0.01" rpy="0 0 0"/>
  <parent link="prismatic_j_base_link"/>
  <child link="prismatic_j_slider_1"/>
  <axis xyz="1.0 0.0 0.0"/>
  <limit upper="0.045" lower="0.0" effort="100" velocity="100"/>
</joint>

<joint name="Rigid 2" type="fixed">
  <origin xyz="0.0 0.0 0.0" rpy="0 0 0"/>
  <parent link="prismatic_j_base_link"/>
  <child link="prismatic_j_APP_1"/>
</joint>

<joint name="Rigid 3" type="fixed">
  <origin xyz="0.055 0.0 -0.01" rpy="0 0 0"/>
  <parent link="prismatic_j_slider_1"/>
  <child link="prismatic_j_APC_1"/>
</joint>

</robot>
