<?xml version="1.0" ?>
<robot name="revolute_yaw_j">

<link name="revolute_yaw_j_base_link">
  <inertial>
    <origin xyz="0.0119561123917724 0.0 -1.3968471162952193e-18" rpy="0 0 0"/>
    <mass value="0.04991384177488204"/>
    <inertia ixx="4e-06" iyy="5e-06" izz="6e-06" ixy="-0.0" iyz="0.0" ixz="0.0"/>
  </inertial>
  <visual>
    <origin xyz="0 0 0" rpy="0 0 0"/>
    <geometry>
      <mesh filename="meshes/revolute_yaw_j_base_link.stl" scale="0.001 0.001 0.001"/>
    </geometry>
    <material name="silver"/>
  </visual>
  <collision>
    <origin xyz="0 0 0" rpy="0 0 0"/>
    <geometry>
      <mesh filename="meshes/revolute_yaw_j_base_link.stl" scale="0.001 0.001 0.001"/>
    </geometry>
  </collision>
</link>

<link name="revolute_yaw_j_driven_1">
  <inertial>
    <origin xyz="0.00957079383950224 3.0757571452879026e-18 1.5378785726439513e-18" rpy="0 0 0"/>
    <mass value="0.045336483118164767"/>
    <inertia ixx="2e-06" iyy="4e-06" izz="4e-06" ixy="0.0" iyz="-0.0" ixz="-0.0"/>
  </inertial>
  <visual>
    <origin xyz="-0.02 -0.0 -0.0" rpy="0 0 0"/>
    <geometry>
      <mesh filename="meshes/revolute_yaw_j_driven_1.stl" scale="0.001 0.001 0.001"/>
    </geometry>
    <material name="silver"/>
  </visual>
  <collision>
    <origin xyz="-0.02 -0.0 -0.0" rpy="0 0 0"/>
    <geometry>
      <mesh filename="meshes/revolute_yaw_j_driven_1.stl" scale="0.001 0.001 0.001"/>
    </geometry>
  </collision>
</link>

<link name="revolute_yaw_j_APC_1">
  <inertial>
    <origin xyz="0.0 0.0 0.0" rpy="0 0 0"/>
    <mass value="3.288200310757317e-05"/>
    <inertia ixx="0.0" iyy="0.0" izz="0.0" ixy="-0.0" iyz="-0.0" ixz="0.0"/>
  </inertial>
  
  
</link>

<link name="revolute_yaw_j_APP_1">
  <inertial>
    <origin xyz="-1.387750568652916e-18 0.0 0.0" rpy="0 0 0"/>
    <mass value="3.288200310757317e-05"/>
    <inertia ixx="0.0" iyy="0.0" izz="0.0" ixy="-0.0" iyz="-0.0" ixz="0.0"/>
  </inertial>
  
  
</link>

<joint name="Revolute 1" type="revolute">
  <origin xyz="0.02 0.0 0.0" rpy="0 0 0"/>
  <parent link="revolute_yaw_j_base_link"/>
  <child link="revolute_yaw_j_driven_1"/>
  <axis xyz="0.0 1.0 0.0"/>
  <limit upper="1.570796" lower="-1.570796" effort="100" velocity="100"/>
</joint>

<joint name="Rigid 2" type="fixed">
  <origin xyz="0.02 0.0 0.0" rpy="0 0 0"/>
  <parent link="revolute_yaw_j_driven_1"/>
  <child link="revolute_yaw_j_APC_1"/>
</joint>

<joint name="Rigid 3" type="fixed">
  <origin xyz="0.0 0.0 0.0" rpy="0 0 0"/>
  <parent link="revolute_yaw_j_base_link"/>
  <child link="revolute_yaw_j_APP_1"/>
</joint>

</robot>
