<?xml version="1.0" ?>
<robot name="revolute_roll_j">

<link name="revolute_roll_j_base_link">
  <inertial>
    <origin xyz="-8.834874115176805e-19 1.0456780305240966e-12 0.001000000000000001" rpy="0 0 0"/>
    <mass value="0.001233075116533942"/>
    <inertia ixx="0.0" iyy="0.0" izz="0.0" ixy="-0.0" iyz="-0.0" ixz="-0.0"/>
  </inertial>
  <visual>
    <origin xyz="0 0 0" rpy="0 0 0"/>
    <geometry>
      <mesh filename="meshes/revolute_roll_j_base_link.stl" scale="0.001 0.001 0.001"/>
    </geometry>
    <material name="silver"/>
  </visual>
  <collision>
    <origin xyz="0 0 0" rpy="0 0 0"/>
    <geometry>
      <mesh filename="meshes/revolute_roll_j_base_link.stl" scale="0.001 0.001 0.001"/>
    </geometry>
  </collision>
</link>

<link name="revolute_roll_j_link_1">
  <inertial>
    <origin xyz="2.089650619862512e-13 8.477091992890196e-15 0.0005" rpy="0 0 0"/>
    <mass value="2.466150233067882e-05"/>
    <inertia ixx="0.0" iyy="0.0" izz="0.0" ixy="0.0" iyz="-0.0" ixz="0.0"/>
  </inertial>
  <visual>
    <origin xyz="-0.0 -0.0 -0.002" rpy="0 0 0"/>
    <geometry>
      <mesh filename="meshes/revolute_roll_j_link_1.stl" scale="0.001 0.001 0.001"/>
    </geometry>
    <material name="silver"/>
  </visual>
  <collision>
    <origin xyz="-0.0 -0.0 -0.002" rpy="0 0 0"/>
    <geometry>
      <mesh filename="meshes/revolute_roll_j_link_1.stl" scale="0.001 0.001 0.001"/>
    </geometry>
  </collision>
</link>

<link name="revolute_roll_j_APP_1">
  <inertial>
    <origin xyz="3.7077246103291944e-20 2.915969213287113e-19 -1.6653345369377347e-18" rpy="0 0 0"/>
    <mass value="4.110250388446646e-06"/>
    <inertia ixx="0.0" iyy="0.0" izz="0.0" ixy="0.0" iyz="0.0" ixz="0.0"/>
  </inertial>
  
  
</link>

<link name="revolute_roll_j_APC_1">
  <inertial>
    <origin xyz="1.1644688946060454e-18 1.0161167719761161e-19 4.336808689942018e-19" rpy="0 0 0"/>
    <mass value="4.110250388446646e-06"/>
    <inertia ixx="0.0" iyy="0.0" izz="0.0" ixy="-0.0" iyz="-0.0" ixz="0.0"/>
  </inertial>
  
  
</link>

<joint name="Revolute 1" type="continuous">
  <origin xyz="0.0 0.0 0.002" rpy="0 0 0"/>
  <parent link="revolute_roll_j_base_link"/>
  <child link="revolute_roll_j_link_1"/>
  <axis xyz="0.0 0.0 1.0"/>
</joint>

<joint name="Rigid 2" type="fixed">
  <origin xyz="0.0 0.0 0.0" rpy="0 0 0"/>
  <parent link="revolute_roll_j_base_link"/>
  <child link="revolute_roll_j_APP_1"/>
</joint>

<joint name="Rigid 3" type="fixed">
  <origin xyz="0.0 0.0 0.001" rpy="0 0 0"/>
  <parent link="revolute_roll_j_link_1"/>
  <child link="revolute_roll_j_APC_1"/>
</joint>

</robot>
